Workbook

Sheet 1 · KAPAK
A1: KEŞİF ÖZETİ VE METRAJ CETVELLERİ · BILL OF QUANTITIES
B3: PROJE ADI (PROJECT NAME) | D3: MALTEPE / İDEALTEPE — MOBİLYA MAĞAZASI → FONKSİYONEL ANTRENMAN STÜDYOSU
B4: İŞİN ADI (PACKAGE NAME) | D4: Mobilya mağazası → fonksiyonel antrenman stüdyosu dönüşümü
B5: İŞVEREN (EMPLOYER) | D5: ……………………………… (işveren adı doldurulacak)
B6: YÜKLENİCİ (CONTRACTOR) | D6: ……………………………… (teklif veren firma doldurulacak)
B7: NET İÇ KULLANIM ALANI | D7: 103.78 m² · 10 mahal
B8: REVİZYON (REVISION) | D8: Rev G
B9: TARİH (DATE) | D9: 17 Eylül 2026
B10: PARA BİRİMİ (CURRENCY) | D10: TL · KDV hariç
B11: FİYAT REFERANSI | D11: Mayıs 2025 (Vogelkopp kesin hakedişi) · Eylül 2026'ya eskale
B13: TEKLİF VERENE NOTLAR
B14: 1) MALZEME BİRİM FİYATI ve İŞÇİLİK BİRİM FİYATI sütunları BOŞ bırakılmıştır; teklif veren firma doldurur. Tutar sütunları canlı formülle kendiliğinden hesaplanır.
B15: 2) Miktarlar mimari uygulama projesinden (A-01…A-13) türetilmiş, metraj cetvelleri bu dosyanın «METRAJ» sayfalarında satır satır verilmiştir. Kapı ve pencere boşlukları MİNHA olarak düşülmüştür.
B16: 3) Birim fiyatlara; malzeme, işçilik, şantiye içi yatay-düşey taşıma, iskele, koruma, zayiat, montaj sarfı ve imalat sonrası temizlik dâhildir.
B17: 4) Genel gider ile kâr ve risk bedeli ayrı sütunlarda gösterilecek, birim fiyata gömülmeyecektir.
B18: 5) Tüm imalatlarda numune onayı zorunludur; onaysız sipariş bedeli yükleniciye aittir.
B19: 6) Mevcut duvar kalınlığı, tavan yüksekliği ve şap üst kotu VARSAYIMDIR. Söküm sonrası rölöve ile doğrulanacak, metrajlar bu dosya üzerinden tek yerden güncellenecektir.
B20: 7) Mekanik ve elektrik keşifleri ayrı sayfalardadır; koordinasyon bedeli icmalde ayrıca gösterilir.
B21: 8) KDV oranı imalat cinsine göre %20 / %10 olarak icmalde ayrıştırılmıştır.
B23: HAZIRLAYAN | D23: KONTROL | F23: ONAY
B27: Proje müellifi | D27: Yapı denetim / mimar | F27: İşveren

Sheet 2 · İCMAL
A1: İMALAT İCMALİ · SUMMARY OF WORKS
A2: MALTEPE / İDEALTEPE — MOBİLYA MAĞAZASI → FONKSİYONEL ANTRENMAN STÜDYOSU · Rev G · 17 Eylül 2026 · Tutarlar KDV hariç TL
A4: PAKET NO | B4: UYGULAMA PAKETİ | C4: POZ ADEDİ | D4: TEKLİF TUTARI (KDV hariç) | E4: BÜTÇE TAHMİNİ DÜŞÜK | F4: BÜTÇE TAHMİNİ YÜKSEK | G4: KDV ORANI | H4: KDV DÂHİL TEKLİF | I4: KOORDİNASYON BEDELİ
A5: A | B5: YIKIM · SÖKÜM VE MOLOZ ATMA İŞLERİ | C5: 6 | D5: =SUMIF('3 · KEŞİF ÖZETİ'!$A:$A,"A*",'3 · KEŞİF ÖZETİ'!$Q:$Q) | E5: 155793.6 | F5: 247875.9 | G5: 0.2 | H5: =D5*(1+G5) | I5: =D5*0.20
A6: B | B6: BÖLME DUVAR VE ALÇIPAN İŞLERİ | C6: 3 | D6: =SUMIF('3 · KEŞİF ÖZETİ'!$A:$A,"B*",'3 · KEŞİF ÖZETİ'!$Q:$Q) | E6: 354543 | F6: 450588 | G6: 0.2 | H6: =D6*(1+G6) | I6: =D6*0.20
A7: C | B7: ŞAP VE TESVİYE İŞLERİ | C7: 5 | D7: =SUMIF('3 · KEŞİF ÖZETİ'!$A:$A,"C*",'3 · KEŞİF ÖZETİ'!$Q:$Q) | E7: 86050.2 | F7: 122188.4 | G7: 0.2 | H7: =D7*(1+G7) | I7: =D7*0.20
A8: D | B8: ZEMİN KAPLAMA VE SÜPÜRGELİK İŞLERİ | C8: 9 | D8: =SUMIF('3 · KEŞİF ÖZETİ'!$A:$A,"D*",'3 · KEŞİF ÖZETİ'!$Q:$Q) | E8: 254653.3 | F8: 377584.9 | G8: 0.2 | H8: =D8*(1+G8) | I8: =D8*0.20
A9: E | B9: SERAMİK VE SU YALITIMI İŞLERİ | C9: 5 | D9: =SUMIF('3 · KEŞİF ÖZETİ'!$A:$A,"E*",'3 · KEŞİF ÖZETİ'!$Q:$Q) | E9: 102628.85 | F9: 152964.3 | G9: 0.2 | H9: =D9*(1+G9) | I9: =D9*0.20
A10: F | B10: ASMA TAVAN VE BOYA İŞLERİ | C10: 9 | D10: =SUMIF('3 · KEŞİF ÖZETİ'!$A:$A,"F*",'3 · KEŞİF ÖZETİ'!$Q:$Q) | E10: 309828.75 | F10: 466314.9 | G10: 0.2 | H10: =D10*(1+G10) | I10: =D10*0.20
A11: G | B11: DOĞRAMA, CAM VE AYNA İŞLERİ | C11: 12 | D11: =SUMIF('3 · KEŞİF ÖZETİ'!$A:$A,"G*",'3 · KEŞİF ÖZETİ'!$Q:$Q) | E11: 282731.6 | F11: 457614.8 | G11: 0.2 | H11: =D11*(1+G11) | I11: =D11*0.20
A12: H | B12: SABİT MOBİLYA İŞLERİ | C12: 5 | D12: =SUMIF('3 · KEŞİF ÖZETİ'!$A:$A,"H*",'3 · KEŞİF ÖZETİ'!$Q:$Q) | E12: 173900 | F12: 290500 | G12: 0.2 | H12: =D12*(1+G12) | I12: =D12*0.20
A13: I | B13: YANGIN GÜVENLİK VE İŞARETLEME | C13: 3 | D13: =SUMIF('3 · KEŞİF ÖZETİ'!$A:$A,"I*",'3 · KEŞİF ÖZETİ'!$Q:$Q) | E13: 50750 | F13: 84100 | G13: 0.2 | H13: =D13*(1+G13) | I13: =D13*0.20
A14: J | B14: ŞANTİYE GENEL GİDERLERİ | C14: 4 | D14: =SUMIF('3 · KEŞİF ÖZETİ'!$A:$A,"J*",'3 · KEŞİF ÖZETİ'!$Q:$Q) | E14: 324314.4 | F14: 496872.8 | G14: 0.2 | H14: =D14*(1+G14) | I14: =D14*0.20
A15: K | B15: MEKANİK TESİSAT İŞLERİ | C15: 37 | D15: ='5 · MEKANİK KEŞİF'!$H$3 | E15: 540728 | F15: 909501 | G15: 0.2 | H15: =D15*(1+G15) | I15: =D15*0.1
A16: L | B16: ELEKTRİK TESİSAT İŞLERİ | C16: 36 | D16: ='6 · ELEKTRİK KEŞİF'!$H$3 | E16: 412220 | F16: 698140 | G16: 0.2 | H16: =D16*(1+G16) | I16: =D16*0.1
B17: DOĞRUDAN İMALAT TOPLAMI | D17: =SUM(D5:D16) | E17: =SUM(E5:E16) | F17: =SUM(F5:F16) | H17: =SUM(H5:H16) | I17: =SUM(I5:I16)
B19: MALİYET KURGUSU
A20: 1 | B20: Doğrudan imalat toplamı (A–L) | D20: =D17 | E20: =E17 | F20: =F17
A21: 2 | B21: Yüklenici koordinasyon / genel gider ve kâr bedeli — inşaat %20, mekanik-elektrik %10 (referans proje oranları) | D21: =I17 | E21: =E17*0.18 | F21: =F17*0.18
A22: 3 | B22: Beklenmedik giderler payı %15 — ıslak hacim ve mevcut durum belirsizliği | D22: =(D20+D21)*0.15 | E22: =(E20+E21)*0.15 | F22: =(F20+F21)*0.15
B23: SÖZLEŞME BEDELİ (KDV HARİÇ) | D23: =D20+D21+D22 | E23: =E20+E21+E22 | F23: =F20+F21+F22
B24: KDV (%20 · imalat cinsine göre icmal satırlarından) | D24: =D23*0.20 | E24: =E23*0.20 | F24: =F23*0.20
B25: GENEL TOPLAM (KDV DÂHİL) | D25: =D23+D24 | E25: =E23+E24 | F25: =F23+F24
A27: BÜTÇE TAHMİNİ sütunları, işverenin referans projesi (Aqua Florya / Saltbae, Vogelkopp kesin hakedişi 13.05.2025) gerçekleşen birim fiyatlarının Eylül 2026'ya ×1.4 ile eskale edilmesiyle kurulmuştur. TEKLİF TUTARI sütunu, «3 · KEŞİF ÖZETİ» sayfasına girilen birim fiyatlardan canlı hesaplanır.

Sheet 3 · KEŞİF ÖZETİ
A1: KEŞİF ÖZETİ · BILL OF QUANTITIES — MİMARİ İMALATLAR
A2: MALTEPE / İDEALTEPE — MOBİLYA MAĞAZASI → FONKSİYONEL ANTRENMAN STÜDYOSU · Rev G · 17 Eylül 2026 · KDV hariç TL · sarı hücreler teklif veren firma tarafından doldurulacaktır
A4: POZ NO | B4: ŞARTNAME NO | C4: YAPILACAK İŞİN CİNSİ | D4: MAHAL / PROJE REFERANSI | E4: AÇIKLAMA / MARKA | F4: BİRİM | G4: MİKTAR | H4: MALZEME BİRİM FİYATI | I4: MALZEME TOPLAM FİYATI | J4: İŞÇİLİK BİRİM FİYATI | K4: İŞÇİLİK TOPLAM FİYATI | L4: GENEL GİDER (TL) | M4: GENEL GİDER TOPLAM | N4: KÂR + RİSK (TL) | O4: KÂR + RİSK TOPLAM | P4: TOPLAM BİRİM FİYAT | Q4: TOPLAM FİYAT
A5: A | B5: 02 41 00 · YIKIM · SÖKÜM VE MOLOZ ATMA İŞLERİ
A6: A.1.1 | B6: 02 41 00 | C6: Mevcut zemin kaplaması sökümü ve altlık temizliği | D6: Tüm mahaller | E6: — | F6: m² | G6: 103.78 | I6: =$G6*H6 | K6: =$G6*J6 | M6: =$G6*L6 | O6: =$G6*N6 | P6: =H6+J6+L6+N6 | Q6: =$G6*P6
A7: A.1.2 | B7: 02 41 00 | C7: Mevcut asma tavan ve aydınlatma armatürü sökümü | D7: Tüm mahaller | E7: — | F7: m² | G7: 103.78 | I7: =$G7*H7 | K7: =$G7*J7 | M7: =$G7*L7 | O7: =$G7*N7 | P7: =H7+J7+L7+N7 | Q7: =$G7*P7
A8: A.1.3 | B8: 02 41 00 | C8: Islak hacimde mevcut şap kırımı (ort. 70 mm, tesisat boşluğu) | D8: 106·107·109·110 | E8: — | F8: m² | G8: 6.19 | I8: =$G8*H8 | K8: =$G8*J8 | M8: =$G8*L8 | O8: =$G8*N8 | P8: =H8+J8+L8+N8 | Q8: =$G8*P8
A9: A.1.4 | B9: 02 41 00 | C9: Mevcut sıva üstü elektrik tesisatı ve tablosu sökümü | D9: Tüm mahaller | E9: — | F9: tk | G9: 1 | I9: =$G9*H9 | K9: =$G9*J9 | M9: =$G9*L9 | O9: =$G9*N9 | P9: =H9+J9+L9+N9 | Q9: =$G9*P9
A10: A.1.5 | B10: 02 41 00 | C10: Mevcut mağaza rafı, teşhir ünitesi ve mobilya sökümü | D10: 101–104 | E10: — | F10: tk | G10: 1 | I10: =$G10*H10 | K10: =$G10*J10 | M10: =$G10*L10 | O10: =$G10*N10 | P10: =H10+J10+L10+N10 | Q10: =$G10*P10
A11: A.1.6 | B11: 02 41 00 | C11: Moloz çuvallama, yatay-düşey taşıma ve döküm sahasına nakli | D11: Tüm mahaller | E11: — | F11: m³ | G11: 13.47 | I11: =$G11*H11 | K11: =$G11*J11 | M11: =$G11*L11 | O11: =$G11*N11 | P11: =H11+J11+L11+N11 | Q11: =$G11*P11
A12: B | B12: 09 21 16 · BÖLME DUVAR VE ALÇIPAN İŞLERİ
A13: B.1.1 | B13: 09 21 16 | C13: D2 alçıpan bölme — 50 mm C profil @400 + 40 mm taşyünü + her yüz 2×12,5 mm A tipi alçıpan (toplam 100 mm) | D13: 105 · 108 cephe | E13: Knauf · Lafarge · Dalsan — eşdeğer | F13: m² | G13: 28.44 | I13: =$G13*H13 | K13: =$G13*J13 | M13: =$G13*L13 | O13: =$G13*N13 | P13: =H13+J13+L13+N13 | Q13: =$G13*P13
A14: B.1.2 | B14: 09 21 16 | C14: D3 alçıpan bölme — ıslak yüzde 2×12,5 mm H2 (yeşil) alçıpan, kuru yüzde 2×12,5 mm A tipi (toplam 100 mm) | D14: 106·107·109·110 | E14: Knauf · Lafarge · Dalsan — eşdeğer | F14: m² | G14: 60.42 | I14: =$G14*H14 | K14: =$G14*J14 | M14: =$G14*L14 | O14: =$G14*N14 | P14: =H14+J14+L14+N14 | Q14: =$G14*P14
A15: B.1.3 | B15: 09 21 16 | C15: D4 akustik giydirme — bağımsız C profil karkas + 50 mm taşyünü + 12,5 mm akustik + 12,5 mm A tipi alçıpan (toplam 95 mm) | D15: 102 güney çeper | E15: Knauf · Lafarge · Dalsan — eşdeğer | F15: m² | G15: 16.08 | I15: =$G15*H15 | K15: =$G15*J15 | M15: =$G15*L15 | O15: =$G15*N15 | P15: =H15+J15+L15+N15 | Q15: =$G15*P15
A16: C | B16: 03 54 00 · ŞAP VE TESVİYE İŞLERİ
A17: C.1.1 | B17: 03 54 00 | C17: Çimento esaslı kendinden yayılan tesviye şapı 3 mm — Z1 bölgesi (bitmiş kot ±0,00 eşitlemesi) | D17: 102 | E17: Ardex · Weber · Baumit — eşdeğer | F17: m² | G17: 31.76 | I17: =$G17*H17 | K17: =$G17*J17 | M17: =$G17*L17 | O17: =$G17*N17 | P17: =H17+J17+L17+N17 | Q17: =$G17*P17
A18: C.1.2 | B18: 03 54 00 | C18: Çimento esaslı tesviye şapı 30 mm — Z2 bölgesi (bitmiş kot ±0,00 eşitlemesi) | D18: 103 | E18: Ardex · Weber · Baumit — eşdeğer | F18: m² | G18: 22.31 | I18: =$G18*H18 | K18: =$G18*J18 | M18: =$G18*L18 | O18: =$G18*N18 | P18: =H18+J18+L18+N18 | Q18: =$G18*P18
A19: C.1.3 | B19: 03 54 00 | C19: Çimento esaslı tesviye şapı 42 mm — Z3 bölgesi (bitmiş kot ±0,00 eşitlemesi) | D19: 101 · 104 | E19: Ardex · Weber · Baumit — eşdeğer | F19: m² | G19: 32.98 | I19: =$G19*H19 | K19: =$G19*J19 | M19: =$G19*L19 | O19: =$G19*N19 | P19: =H19+J19+L19+N19 | Q19: =$G19*P19
A20: C.1.4 | B20: 03 54 00 | C20: Çimento esaslı tesviye şapı 38 mm — Z5 bölgesi (bitmiş kot ±0,00 eşitlemesi) | D20: 105 · 108 | E20: Ardex · Weber · Baumit — eşdeğer | F20: m² | G20: 10.07 | I20: =$G20*H20 | K20: =$G20*J20 | M20: =$G20*L20 | O20: =$G20*N20 | P20: =H20+J20+L20+N20 | Q20: =$G20*P20
A21: C.1.5 | B21: 03 54 00 | C21: Islak hacim tesisat şapı + süzgeğe %1,5 eğimli eğim şapı (ort. 40 mm) | D21: 106·107·109·110 | E21: Ardex · Weber · Baumit — eşdeğer | F21: m² | G21: 6.19 | I21: =$G21*H21 | K21: =$G21*J21 | M21: =$G21*L21 | O21: =$G21*N21 | P21: =H21+J21+L21+N21 | Q21: =$G21*P21
A22: D | B22: 09 65 00 · ZEMİN KAPLAMA VE SÜPÜRGELİK İŞLERİ
A23: D.1.1 | B23: 09 65 00 | C23: Z1 — Granül kauçuk karo 1000×1000 mm, 40 mm, EPDM %10 taneli, Shore A 55±5 (EN 14041 · Bfl-s1) — puzzle kilitli kuru derz, çeperde 5 mm genleşme boşluğu | D23: 102 | E23: Pavigym · Gerflor · Tarkett — eşdeğer | F23: m² | G23: 31.76 | I23: =$G23*H23 | K23: =$G23*J23 | M23: =$G23*L23 | O23: =$G23*N23 | P23: =H23+J23+L23+N23 | Q23: =$G23*P23
A24: D.1.2 | B24: 09 65 00 | C24: Z2 — Granül kauçuk karo 1000×1000 mm, 20 mm, Shore A 60 (EN 14041 · Bfl-s1) — puzzle kilitli kuru derz | D24: 103 | E24: Pavigym · Gerflor · Tarkett — eşdeğer | F24: m² | G24: 22.31 | I24: =$G24*H24 | K24: =$G24*J24 | M24: =$G24*L24 | O24: =$G24*N24 | P24: =H24+J24+L24+N24 | Q24: =$G24*P24
A25: D.1.3 | B25: 09 65 00 | C25: Z3 — SPC klik LVT 5 mm, 0,55 mm aşınma tabakası (EN ISO 10874 sınıf 33 / AC5) + 2 mm IXPE akustik şilte — çeperde 8 mm genleşme boşluğu | D25: 101 · 104 | E25: Pavigym · Gerflor · Tarkett — eşdeğer | F25: m² | G25: 32.98 | I25: =$G25*H25 | K25: =$G25*J25 | M25: =$G25*L25 | O25: =$G25*N25 | P25: =H25+J25+L25+N25 | Q25: =$G25*P25
A26: D.1.4 | B26: 09 65 00 | C26: Z4 — Porselen seramik 300×300 mm, R11 / B kaymazlık (EN 16165) + C2TE S1 yapıştırıcı | D26: 106 · 107 · 109 · 110 | E26: Pavigym · Gerflor · Tarkett — eşdeğer | F26: m² | G26: 6.19 | I26: =$G26*H26 | K26: =$G26*J26 | M26: =$G26*L26 | O26: =$G26*N26 | P26: =H26+J26+L26+N26 | Q26: =$G26*P26
A27: D.1.5 | B27: 09 65 00 | C27: Z5 — Porselen seramik 600×600 mm, R10, rektifiye, 2 mm derz (EN 14411 BIa) + C2TE yapıştırıcı | D27: 105 · 108 | E27: Pavigym · Gerflor · Tarkett — eşdeğer | F27: m² | G27: 10.07 | I27: =$G27*H27 | K27: =$G27*J27 | M27: =$G27*L27 | O27: =$G27*N27 | P27: =H27+J27+L27+N27 | Q27: =$G27*P27
A28: D.1.6 | B28: 09 65 00 | C28: Kauçuk titreşim yalıtım matı 10 mm (SBR granül 700 kg/m³) — duvara 50 mm yukarı dönüşlü yüzer döşeme | D28: 102 | E28: Pavigym · Gerflor · Tarkett — eşdeğer | F28: m² | G28: 31.76 | I28: =$G28*H28 | K28: =$G28*J28 | M28: =$G28*L28 | O28: =$G28*N28 | P28: =H28+J28+L28+N28 | Q28: =$G28*P28
A29: D.2.1 | B29: 09 65 00 | C29: Kauçuk süpürgelik 100×8 mm — zemin kaplamasıyla aynı malzeme, üst kenarı 45° pahlı | D29: 102 · 103 | E29: Pavigym · Gerflor · Tarkett — eşdeğer | F29: mt | G29: 40.62 | I29: =$G29*H29 | K29: =$G29*J29 | M29: =$G29*L29 | O29: =$G29*N29 | P29: =H29+J29+L29+N29 | Q29: =$G29*P29
A30: D.2.2 | B30: 09 65 00 | C30: MDF lake süpürgelik 80×16 mm — RAL 9003, akrilik mastik ile duvara yalanır | D30: 101 · 104 | E30: Pavigym · Gerflor · Tarkett — eşdeğer | F30: mt | G30: 23.65 | I30: =$G30*H30 | K30: =$G30*J30 | M30: =$G30*L30 | O30: =$G30*N30 | P30: =H30+J30+L30+N30 | Q30: =$G30*P30
A31: D.2.4 | B31: 09 65 00 | C31: Porselen süpürgelik 80 mm — zemin karosundan kesme, rektifiye kenar | D31: 105 · 108 | E31: Pavigym · Gerflor · Tarkett — eşdeğer | F31: mt | G31: 16.17 | I31: =$G31*H31 | K31: =$G31*J31 | M31: =$G31*L31 | O31: =$G31*N31 | P31: =H31+J31+L31+N31 | Q31: =$G31*P31
A32: E | B32: 09 30 00 · SERAMİK VE SU YALITIMI İŞLERİ
A33: E.1.1 | B33: 09 30 00 | C33: D5 duvar seramiği 300×600 mm, rektifiye — duş kabininde tavana kadar | D33: 106 · 109 | E33: Vitra · Kalekim · Weber — eşdeğer | F33: m² | G33: 21.68 | I33: =$G33*H33 | K33: =$G33*J33 | M33: =$G33*L33 | O33: =$G33*N33 | P33: =H33+J33+L33+N33 | Q33: =$G33*P33
A34: E.1.2 | B34: 09 30 00 | C34: D5 duvar seramiği 300×600 mm — WC'de h = 1,60 m | D34: 107 · 110 | E34: Vitra · Kalekim · Weber — eşdeğer | F34: m² | G34: 14.46 | I34: =$G34*H34 | K34: =$G34*J34 | M34: =$G34*L34 | O34: =$G34*N34 | P34: =H34+J34+L34+N34 | Q34: =$G34*P34
A35: E.1.3 | B35: 09 30 00 | C35: Çimento esaslı 2 bileşenli su yalıtımı, 2 kat (EN 14891) — zemin | D35: 106·107·109·110 | E35: Vitra · Kalekim · Weber — eşdeğer | F35: m² | G35: 6.19 | I35: =$G35*H35 | K35: =$G35*J35 | M35: =$G35*L35 | O35: =$G35*N35 | P35: =H35+J35+L35+N35 | Q35: =$G35*P35
A36: E.1.4 | B36: 09 30 00 | C36: Çimento esaslı su yalıtımı, 2 kat — duvarda dönüş (duşta 2,00 m, WC'de 0,30 m) | D36: 106·107·109·110 | E36: Vitra · Kalekim · Weber — eşdeğer | F36: m² | G36: 23.47 | I36: =$G36*H36 | K36: =$G36*J36 | M36: =$G36*L36 | O36: =$G36*N36 | P36: =H36+J36+L36+N36 | Q36: =$G36*P36
A37: E.1.5 | B37: 09 30 00 | C37: Elastik su yalıtım bandı 120 mm — zemin-duvar birleşimi ve köşeler | D37: 106·107·109·110 | E37: Vitra · Kalekim · Weber — eşdeğer | F37: mt | G37: 52.61 | I37: =$G37*H37 | K37: =$G37*J37 | M37: =$G37*L37 | O37: =$G37*N37 | P37: =H37+J37+L37+N37 | Q37: =$G37*P37
A38: F | B38: 09 51 00 · ASMA TAVAN VE BOYA İŞLERİ
A39: F.1.1 | B39: 09 51 00 | C39: T2 Alçıpan asma tavan — kuru hacim — kot +2,75 | D39: 101 · 104 | E39: Knauf · Dyo · Filli Boya — eşdeğer | F39: m² | G39: 32.98 | I39: =$G39*H39 | K39: =$G39*J39 | M39: =$G39*L39 | O39: =$G39*N39 | P39: =H39+J39+L39+N39 | Q39: =$G39*P39
A40: F.1.2 | B40: 09 51 00 | C40: T4 Alçıpan asma tavan — soyunma — kot +2,60 | D40: 105 · 108 | E40: Knauf · Dyo · Filli Boya — eşdeğer | F40: m² | G40: 10.07 | I40: =$G40*H40 | K40: =$G40*J40 | M40: =$G40*L40 | O40: =$G40*N40 | P40: =H40+J40+L40+N40 | Q40: =$G40*P40
A41: F.1.3 | B41: 09 51 00 | C41: T3 Alçıpan asma tavan — ıslak hacim — kot +2,40 | D41: 106 · 107 · 109 · 110 | E41: Knauf · Dyo · Filli Boya — eşdeğer | F41: m² | G41: 6.19 | I41: =$G41*H41 | K41: =$G41*J41 | M41: =$G41*L41 | O41: =$G41*N41 | P41: =H41+J41+L41+N41 | Q41: =$G41*P41
...

Sheet 4 · BÜTÇE TAHMİNİ
A1: İŞVEREN BÜTÇE TAHMİNİ — REFERANS BİRİM FİYATLARLA
A2: Kaynak: Mayıs 2025 (Vogelkopp kesin hakedişi) · Eylül 2026'ya eskale · eskalasyon ×1.4 · KDV hariç TL
A4: POZ NO | B4: YAPILACAK İŞİN CİNSİ | C4: BİRİM | D4: MİKTAR | E4: MALZEME DÜŞÜK | F4: MALZEME YÜKSEK | G4: İŞÇİLİK DÜŞÜK | H4: İŞÇİLİK YÜKSEK | I4: TOPLAM BF DÜŞÜK | J4: TUTAR DÜŞÜK | K4: TUTAR YÜKSEK
A5: A | B5: YIKIM · SÖKÜM VE MOLOZ ATMA İŞLERİ
A6: A.1.1 | B6: Mevcut zemin kaplaması sökümü ve altlık temizliği | C6: m² | D6: 103.78 | E6: 0 | F6: 0 | G6: 240 | H6: 380 | I6: =E6+G6 | J6: =D6*(E6+G6) | K6: =D6*(F6+H6)
A7: A.1.2 | B7: Mevcut asma tavan ve aydınlatma armatürü sökümü | C7: m² | D7: 103.78 | E7: 0 | F7: 0 | G7: 180 | H7: 300 | I7: =E7+G7 | J7: =D7*(E7+G7) | K7: =D7*(F7+H7)
A8: A.1.3 | B8: Islak hacimde mevcut şap kırımı (ort. 70 mm, tesisat boşluğu) | C8: m² | D8: 6.19 | E8: 0 | F8: 0 | G8: 600 | H8: 850 | I8: =E8+G8 | J8: =D8*(E8+G8) | K8: =D8*(F8+H8)
A9: A.1.4 | B9: Mevcut sıva üstü elektrik tesisatı ve tablosu sökümü | C9: tk | D9: 1 | E9: 0 | F9: 0 | G9: 25000 | H9: 42000 | I9: =E9+G9 | J9: =D9*(E9+G9) | K9: =D9*(F9+H9)
A10: A.1.5 | B10: Mevcut mağaza rafı, teşhir ünitesi ve mobilya sökümü | C10: tk | D10: 1 | E10: 0 | F10: 0 | G10: 35000 | H10: 60000 | I10: =E10+G10 | J10: =D10*(E10+G10) | K10: =D10*(F10+H10)
A11: A.1.6 | B11: Moloz çuvallama, yatay-düşey taşıma ve döküm sahasına nakli | C11: m³ | D11: 13.47 | E11: 0 | F11: 0 | G11: 3600 | H11: 5200 | I11: =E11+G11 | J11: =D11*(E11+G11) | K11: =D11*(F11+H11)
A12: B | B12: BÖLME DUVAR VE ALÇIPAN İŞLERİ
A13: B.1.1 | B13: D2 alçıpan bölme — 50 mm C profil @400 + 40 mm taşyünü + her yüz 2×12,5 mm A tipi alçıpan (toplam 100 mm) | C13: m² | D13: 28.44 | E13: 1900 | F13: 2350 | G13: 1300 | H13: 1700 | I13: =E13+G13 | J13: =D13*(E13+G13) | K13: =D13*(F13+H13)
A14: B.1.2 | B14: D3 alçıpan bölme — ıslak yüzde 2×12,5 mm H2 (yeşil) alçıpan, kuru yüzde 2×12,5 mm A tipi (toplam 100 mm) | C14: m² | D14: 60.42 | E14: 2250 | F14: 2800 | G14: 1300 | H14: 1700 | I14: =E14+G14 | J14: =D14*(E14+G14) | K14: =D14*(F14+H14)
A15: B.1.3 | B15: D4 akustik giydirme — bağımsız C profil karkas + 50 mm taşyünü + 12,5 mm akustik + 12,5 mm A tipi alçıpan (toplam 95 mm) | C15: m² | D15: 16.08 | E15: 1900 | F15: 2450 | G15: 1150 | H15: 1500 | I15: =E15+G15 | J15: =D15*(E15+G15) | K15: =D15*(F15+H15)
A16: C | B16: ŞAP VE TESVİYE İŞLERİ
A17: C.1.1 | B17: Çimento esaslı kendinden yayılan tesviye şapı 3 mm — Z1 bölgesi (bitmiş kot ±0,00 eşitlemesi) | C17: m² | D17: 31.76 | E17: 320 | F17: 480 | G17: 260 | H17: 380 | I17: =E17+G17 | J17: =D17*(E17+G17) | K17: =D17*(F17+H17)
A18: C.1.2 | B18: Çimento esaslı tesviye şapı 30 mm — Z2 bölgesi (bitmiş kot ±0,00 eşitlemesi) | C18: m² | D18: 22.31 | E18: 420 | F18: 580 | G18: 420 | H18: 600 | I18: =E18+G18 | J18: =D18*(E18+G18) | K18: =D18*(F18+H18)
A19: C.1.3 | B19: Çimento esaslı tesviye şapı 42 mm — Z3 bölgesi (bitmiş kot ±0,00 eşitlemesi) | C19: m² | D19: 32.98 | E19: 520 | F19: 720 | G19: 460 | H19: 650 | I19: =E19+G19 | J19: =D19*(E19+G19) | K19: =D19*(F19+H19)
A20: C.1.4 | B20: Çimento esaslı tesviye şapı 38 mm — Z5 bölgesi (bitmiş kot ±0,00 eşitlemesi) | C20: m² | D20: 10.07 | E20: 480 | F20: 680 | G20: 440 | H20: 620 | I20: =E20+G20 | J20: =D20*(E20+G20) | K20: =D20*(F20+H20)
A21: C.1.5 | B21: Islak hacim tesisat şapı + süzgeğe %1,5 eğimli eğim şapı (ort. 40 mm) | C21: m² | D21: 6.19 | E21: 560 | F21: 780 | G21: 620 | H21: 880 | I21: =E21+G21 | J21: =D21*(E21+G21) | K21: =D21*(F21+H21)
A22: D | B22: ZEMİN KAPLAMA VE SÜPÜRGELİK İŞLERİ
A23: D.1.1 | B23: Z1 — Granül kauçuk karo 1000×1000 mm, 40 mm, EPDM %10 taneli, Shore A 55±5 (EN 14041 · Bfl-s1) — puzzle kilitli kuru derz, çeperde 5 mm genleşme boşluğu | C23: m² | D23: 31.76 | E23: 2400 | F23: 3400 | G23: 350 | H23: 520 | I23: =E23+G23 | J23: =D23*(E23+G23) | K23: =D23*(F23+H23)
A24: D.1.2 | B24: Z2 — Granül kauçuk karo 1000×1000 mm, 20 mm, Shore A 60 (EN 14041 · Bfl-s1) — puzzle kilitli kuru derz | C24: m² | D24: 22.31 | E24: 1350 | F24: 1950 | G24: 300 | H24: 450 | I24: =E24+G24 | J24: =D24*(E24+G24) | K24: =D24*(F24+H24)
A25: D.1.3 | B25: Z3 — SPC klik LVT 5 mm, 0,55 mm aşınma tabakası (EN ISO 10874 sınıf 33 / AC5) + 2 mm IXPE akustik şilte — çeperde 8 mm genleşme boşluğu | C25: m² | D25: 32.98 | E25: 950 | F25: 1500 | G25: 420 | H25: 620 | I25: =E25+G25 | J25: =D25*(E25+G25) | K25: =D25*(F25+H25)
A26: D.1.4 | B26: Z4 — Porselen seramik 300×300 mm, R11 / B kaymazlık (EN 16165) + C2TE S1 yapıştırıcı | C26: m² | D26: 6.19 | E26: 750 | F26: 1150 | G26: 980 | H26: 1350 | I26: =E26+G26 | J26: =D26*(E26+G26) | K26: =D26*(F26+H26)
A27: D.1.5 | B27: Z5 — Porselen seramik 600×600 mm, R10, rektifiye, 2 mm derz (EN 14411 BIa) + C2TE yapıştırıcı | C27: m² | D27: 10.07 | E27: 850 | F27: 1350 | G27: 980 | H27: 1350 | I27: =E27+G27 | J27: =D27*(E27+G27) | K27: =D27*(F27+H27)
A28: D.1.6 | B28: Kauçuk titreşim yalıtım matı 10 mm (SBR granül 700 kg/m³) — duvara 50 mm yukarı dönüşlü yüzer döşeme | C28: m² | D28: 31.76 | E28: 650 | F28: 980 | G28: 180 | H28: 280 | I28: =E28+G28 | J28: =D28*(E28+G28) | K28: =D28*(F28+H28)
A29: D.2.1 | B29: Kauçuk süpürgelik 100×8 mm — zemin kaplamasıyla aynı malzeme, üst kenarı 45° pahlı | C29: mt | D29: 40.62 | E29: 210 | F29: 330 | G29: 140 | H29: 220 | I29: =E29+G29 | J29: =D29*(E29+G29) | K29: =D29*(F29+H29)
A30: D.2.2 | B30: MDF lake süpürgelik 80×16 mm — RAL 9003, akrilik mastik ile duvara yalanır | C30: mt | D30: 23.65 | E30: 240 | F30: 380 | G30: 160 | H30: 250 | I30: =E30+G30 | J30: =D30*(E30+G30) | K30: =D30*(F30+H30)
A31: D.2.4 | B31: Porselen süpürgelik 80 mm — zemin karosundan kesme, rektifiye kenar | C31: mt | D31: 16.17 | E31: 180 | F31: 290 | G31: 200 | H31: 310 | I31: =E31+G31 | J31: =D31*(E31+G31) | K31: =D31*(F31+H31)
A32: E | B32: SERAMİK VE SU YALITIMI İŞLERİ
A33: E.1.1 | B33: D5 duvar seramiği 300×600 mm, rektifiye — duş kabininde tavana kadar | C33: m² | D33: 21.68 | E33: 780 | F33: 1250 | G33: 1015 | H33: 1400 | I33: =E33+G33 | J33: =D33*(E33+G33) | K33: =D33*(F33+H33)
A34: E.1.2 | B34: D5 duvar seramiği 300×600 mm — WC'de h = 1,60 m | C34: m² | D34: 14.46 | E34: 780 | F34: 1250 | G34: 1015 | H34: 1400 | I34: =E34+G34 | J34: =D34*(E34+G34) | K34: =D34*(F34+H34)
A35: E.1.3 | B35: Çimento esaslı 2 bileşenli su yalıtımı, 2 kat (EN 14891) — zemin | C35: m² | D35: 6.19 | E35: 480 | F35: 700 | G35: 380 | H35: 560 | I35: =E35+G35 | J35: =D35*(E35+G35) | K35: =D35*(F35+H35)
A36: E.1.4 | B36: Çimento esaslı su yalıtımı, 2 kat — duvarda dönüş (duşta 2,00 m, WC'de 0,30 m) | C36: m² | D36: 23.47 | E36: 480 | F36: 700 | G36: 420 | H36: 620 | I36: =E36+G36 | J36: =D36*(E36+G36) | K36: =D36*(F36+H36)
A37: E.1.5 | B37: Elastik su yalıtım bandı 120 mm — zemin-duvar birleşimi ve köşeler | C37: mt | D37: 52.61 | E37: 95 | F37: 160 | G37: 120 | H37: 190 | I37: =E37+G37 | J37: =D37*(E37+G37) | K37: =D37*(F37+H37)
A38: F | B38: ASMA TAVAN VE BOYA İŞLERİ
A39: F.1.1 | B39: T2 Alçıpan asma tavan — kuru hacim — kot +2,75 | C39: m² | D39: 32.98 | E39: 1050 | F39: 1400 | G39: 950 | H39: 1300 | I39: =E39+G39 | J39: =D39*(E39+G39) | K39: =D39*(F39+H39)
A40: F.1.2 | B40: T4 Alçıpan asma tavan — soyunma — kot +2,60 | C40: m² | D40: 10.07 | E40: 1050 | F40: 1400 | G40: 950 | H40: 1300 | I40: =E40+G40 | J40: =D40*(E40+G40) | K40: =D40*(F40+H40)
A41: F.1.3 | B41: T3 Alçıpan asma tavan — ıslak hacim — kot +2,40 | C41: m² | D41: 6.19 | E41: 1250 | F41: 1650 | G41: 980 | H41: 1350 | I41: =E41+G41 | J41: =D41*(E41+G41) | K41: =D41*(F41+H41)
...

Sheet 5 · MEKANİK KEŞİF
A1: MEKANİK KEŞİF · KEŞİF ÖZETİ
A2: MALTEPE / İDEALTEPE — MOBİLYA MAĞAZASI → FONKSİYONEL ANTRENMAN STÜDYOSU · Rev G · KDV hariç TL · sarı hücre teklif verence doldurulur
H3: =F42
A4: POZ NO | B4: YAPILACAK İŞİN CİNSİ | C4: BİRİM | D4: MİKTAR | E4: BİRİM FİYAT (teklif) | F4: TUTAR (teklif) | G4: BÜTÇE DÜŞÜK | H4: BÜTÇE YÜKSEK
A5: 06.01 | B5: Kanal tipi taze hava fanı — 1.000 m³/h / 250 Pa, hız kontrollü | C5: adet | D5: 1 | F5: =D5*E5 | G5: 18500 | H5: 31000
A6: 06.02 | B6: Kanal tipi egzoz fanı — 760 m³/h / 200 Pa | C6: adet | D6: 1 | F6: =D6*E6 | G6: 14500 | H6: 24000
A7: 06.03 | B7: Islak hacim egzoz fanı — 240 m³/h, sessiz tip, nem sensörlü | C7: adet | D7: 1 | F7: =D7*E7 | G7: 6500 | H7: 11500
A8: 06.04 | B8: Galvaniz dikdörtgen kanal 500×150 — besleme ana hattı | C8: m | D8: 16.8 | F8: =D8*E8 | G8: 22680 | H8: 36960
A9: 06.05 | B9: Galvaniz dikdörtgen kanal 400×150 — egzoz ana hattı | C9: m | D9: 10.5 | F9: =D9*E9 | G9: 12075 | H9: 19950
A10: 06.06 | B10: Spiro kanal Ø200 — menfez branşmanları | C10: m | D10: 4.4 | F10: =D10*E10 | G10: 2728 | H10: 4620
A11: 06.06b | B11: Spiro kanal Ø125 — ıslak hacim valf branşmanları | C11: m | D11: 3 | F11: =D11*E11 | G11: 1260 | H11: 2160
A12: 06.07 | B12: Spiro kanal Ø160 — ıslak hacim egzoz hattı | C12: m | D12: 15 | F12: =D12*E12 | G12: 8100 | H12: 13500
A13: 06.08 | B13: Çift sıra ayarlı besleme menfezi 300×150 + plenum | C13: adet | D13: 4 | F13: =D13*E13 | G13: 9600 | H13: 15600
A14: 06.09 | B14: Egzoz menfezi 300×150 + plenum | C14: adet | D14: 3 | F14: =D14*E14 | G14: 6300 | H14: 10200
A15: 06.10 | B15: Tavan egzoz valfi Ø160 (duş / WC) | C15: adet | D15: 4 | F15: =D15*E15 | G15: 3800 | H15: 6400
A16: 06.11 | B16: Debi ayar damperi (branşman başı) | C16: adet | D16: 7 | F16: =D16*E16 | G16: 8050 | H16: 13300
... A41: 06.41 | B41: Tesisat basınç testi, dezenfeksiyon ve teslim raporu | C41: götürü | D41: 1 | F41: =D41*E41 | G41: 9500 | H41: 17000
A42: TOPLAM (KDV hariç) | F42: =SUM(F5:F41) | G42: =SUM(G5:G41) | H42: =SUM(H5:H41)

Sheet 6 · ELEKTRİK KEŞİF
A1: ELEKTRİK KEŞİF · KEŞİF ÖZETİ
A2: MALTEPE / İDEALTEPE — MOBİLYA MAĞAZASI → FONKSİYONEL ANTRENMAN STÜDYOSU · Rev G · KDV hariç TL · sarı hücre teklif verence doldurulur
H3: =F41
A4: POZ NO | B4: YAPILACAK İŞİN CİNSİ | C4: BİRİM | D4: MİKTAR | E4: BİRİM FİYAT (teklif) | F4: TUTAR (teklif) | G4: BÜTÇE DÜŞÜK | H4: BÜTÇE YÜKSEK
A5: 05.01 | B5: Ana dağıtım panosu — sıva üstü metal, 36 modül, montajlı | C5: adet | D5: 1 | F5: =D5*E5 | G5: 22000 | H5: 37000
A6: 05.02 | B6: Ana kesici 3×40 A, C eğrisi | C6: adet | D6: 1 | F6: =D6*E6 | G6: 3200 | H6: 5400
A7: 05.03 | B7: Kaçak akım rölesi 4×40 A / 30 mA (genel + ıslak hacim ayrı) | C7: adet | D7: 2 | F7: =D7*E7 | G7: 8400 | H7: 14000
A8: 05.04 | B8: Otomatik sigorta (1×6 / 1×10 / 1×16 / 1×32 A) | C8: adet | D8: 22 | F8: =D8*E8 | G8: 13640 | H8: 23100
A9: 05.05 | B9: Parafudr Tip 2 (aşırı gerilim koruma) | C9: adet | D9: 1 | F9: =D9*E9 | G9: 6800 | H9: 11500
A10: 05.06 | B10: NYY kolon hattı 5×10 mm² — sayaçtan panoya | C10: m | D10: 22 | F10: =D10*E10 | G10: 17160 | H10: 28600
A11: 05.07 | B11: Pano etiketleme, tek hat şeması çerçevesi ve fonksiyon testi | C11: götürü | D11: 1 | F11: =D11*E11 | G11: 6500 | H11: 11000
A12: 05.10 | B12: Lineer LED armatür 40 W / 4400 lm, 1.200 mm (montaj dahil) | C12: adet | D12: 15 | F12: =D12*E12 | G12: 21000 | H12: 39000
A13: 05.11 | B13: IP44 downlight 18 W / 1800 lm — ıslak hacim ve soyunma | C13: adet | D13: 6 | F13: =D13*E13 | G13: 5100 | H13: 9300
A14: 05.12 | B14: Acil aydınlatma armatürü — 3 saat bataryalı | C14: adet | D14: 5 | F14: =D14*E14 | G14: 6250 | H14: 11000
A15: 05.13 | B15: Acil çıkış yönlendirme armatürü | C15: adet | D15: 3 | F15: =D15*E15 | G15: 3450 | H15: 5850
A16: 05.14 | B16: Aydınlatma linyesi NHXMH 3×1,5 mm² — spiral boru ve işçilik dâhil | C16: m | D16: 42 | F16: =D16*E16 | G16: 4620 | H16: 7770
... A40: 05.48 | B40: Topraklama direnci ölçümü, izolasyon testi ve rapor | C40: götürü | D40: 1 | F40: =D40*E40 | G40: 7500 | H40: 13000
A41: TOPLAM (KDV hariç) | F41: =SUM(F5:F40) | G41: =SUM(G5:G40) | H41: =SUM(H5:H40)

Sheet 7 · METRAJ
A1: METRAJ CETVELLERİ · MEASUREMENT SHEETS
A2: MALTEPE / İDEALTEPE — MOBİLYA MAĞAZASI → FONKSİYONEL ANTRENMAN STÜDYOSU · Rev G · 17 Eylül 2026 · Boşluklar MİNHA olarak (−) satırla düşülmüştür. Ölçüler mimari uygulama projesinden türetilmiştir.
A4: POZ NO: A.1.1 Mevcut zemin kaplaması sökümü ve altlık temizliği
A5: MAHAL: | B5: Tüm mahaller | F5: BİRİM: | G5: m² | H5: PROJE REF: | I5: A-01…A-13
A6: S.NO | B6: YAPILACAK İMALAT AÇIKLAMASI | C6: BİRİM | D6: ADET | E6: EN (m) | F6: BOY (m) | G6: YÜKSEKLİK (m) | H6: TOPLANAN (+) | I6: ÇIKARILAN (−)
A7: 1 | B7: 101 GİRİŞ · BANKO · SİRKÜLASYON | C7: m² | D7: 1 | H7: 15.65
A8: 2 | B8: 102 ARENA · SERBEST AĞIRLIK | C8: m² | D8: 1 | H8: 31.76
A9: 3 | B9: 103 FONKSİYONEL · KARDİYO | C9: m² | D9: 1 | H9: 22.31
A10: 4 | B10: 104 DİNLENME SALONU | C10: m² | D10: 1 | H10: 17.33
A11: 5 | B11: 105 ERKEK SOYUNMA | C11: m² | D11: 1 | H11: 4.48
A12: 6 | B12: 106 ERKEK DUŞ | C12: m² | D12: 1 | H12: 1.76
A13: 7 | B13: 107 ERKEK WC | C13: m² | D13: 1 | H13: 1.75
A14: 8 | B14: 108 KADIN SOYUNMA | C14: m² | D14: 1 | H14: 5.59
A15: 9 | B15: 109 KADIN DUŞ | C15: m² | D15: 1 | H15: 1.39
A16: 10 | B16: 110 KADIN WC | C16: m² | D16: 1 | H16: 1.29
A17: 11 | B17: İç bölme duvar payı (mevcut hâlde tek hacim) | C17: m² | D17: 1 | H17: 0.47
A18: KISMİ YEKÜN | H18: =SUM(H7:H17) | I18: =SUM(I7:I17)
A19: SAYFA YEKÜNÜ · POZ A.1.1 METRAJI | H19: =H18-I18
A21: POZ NO: A.1.2 Mevcut asma tavan ve aydınlatma armatürü sökümü
A22: MAHAL: | B22: Tüm mahaller | F22: BİRİM: | G22: m² | H22: PROJE REF: | I22: A-01…A-13
A23: S.NO | B23: YAPILACAK İMALAT AÇIKLAMASI | C23: BİRİM | D23: ADET | E23: EN (m) | F23: BOY (m) | G23: YÜKSEKLİK (m) | H23: TOPLANAN (+) | I23: ÇIKARILAN (−)
A24: 1 | B24: 101 GİRİŞ · BANKO · SİRKÜLASYON | C24: m² | D24: 1 | H24: 15.65
A25: 2 | B25: 102 ARENA · SERBEST AĞIRLIK | C25: m² | D25: 1 | H25: 31.76
A26: 3 | B26: 103 FONKSİYONEL · KARDİYO | C26: m² | D26: 1 | H26: 22.31
A27: 4 | B27: 104 DİNLENME SALONU | C27: m² | D27: 1 | H27: 17.33
A28: 5 | B28: 105 ERKEK SOYUNMA | C28: m² | D28: 1 | H28: 4.48
A29: 6 | B29: 106 ERKEK DUŞ | C29: m² | D29: 1 | H29: 1.76
A30: 7 | B30: 107 ERKEK WC | C30: m² | D30: 1 | H30: 1.75
A31: 8 | B31: 108 KADIN SOYUNMA | C31: m² | D31: 1 | H31: 5.59
A32: 9 | B32: 109 KADIN DUŞ | C32: m² | D32: 1 | H32: 1.39
A33: 10 | B33: 110 KADIN WC | C33: m² | D33: 1 | H33: 1.29
A34: 11 | B34: İç bölme duvar payı (mevcut hâlde tek hacim) | C34: m² | D34: 1 | H34: 0.47
A35: KISMİ YEKÜN | H35: =SUM(H24:H34) | I35: =SUM(I24:I34)
A36: SAYFA YEKÜNÜ · POZ A.1.2 METRAJI | H36: =H35-I35
A38: POZ NO: A.1.3 Islak hacimde mevcut şap kırımı (ort. 70 mm, tesisat boşluğu)
A39: MAHAL: | B39: 106·107·109·110 | F39: BİRİM: | G39: m² | H39: PROJE REF: | I39: A-01…A-13
A40: S.NO | B40: YAPILACAK İMALAT AÇIKLAMASI | C40: BİRİM | D40: ADET | E40: EN (m) | F40: BOY (m) | G40: YÜKSEKLİK (m) | H40: TOPLANAN (+) | I40: ÇIKARILAN (−)
A41: 1 | B41: 106 ERKEK DUŞ | C41: m² | D41: 1 | H41: 1.76
A42: 2 | B42: 107 ERKEK WC | C42: m² | D42: 1 | H42: 1.75
A43: 3 | B43: 109 KADIN DUŞ | C43: m² | D43: 1 | H43: 1.39
...
