Workbook

Sheet 1 · Özet
A1: ELEKTRIK — MALİYET ÖZETİ
A2: Rev H · 17 Eylül 2026 · Eylül 2026 · Aqua Florya / Saltbae kesin hakedişi (Mayıs 2025) birim fiyatları ×1,40 eskalasyonla · Ekipman işverence temin edilmiştir, bütçe dışıdır.
A4: Sistem | B4: Teklif tutarı (TL) | C4: Referans düşük (TL) | D4: Referans yüksek (TL) | E4: Poz adedi
A5: Ana dağıtım | B5: ='2 · Detay metraj'!G4+'2 · Detay metraj'!G5+'2 · Detay metraj'!G6+'2 · Detay metraj'!G7+'2 · Detay metraj'!G8+'2 · Detay metraj'!G9+'2 · Detay metraj'!G10 | C5: ='2 · Detay metraj'!H4+'2 · Detay metraj'!H5+'2 · Detay metraj'!H6+'2 · Detay metraj'!H7+'2 · Detay metraj'!H8+'2 · Detay metraj'!H9+'2 · Detay metraj'!H10 | D5: ='2 · Detay metraj'!I4+'2 · Detay metraj'!I5+'2 · Detay metraj'!I6+'2 · Detay metraj'!I7+'2 · Detay metraj'!I8+'2 · Detay metraj'!I9+'2 · Detay metraj'!I10 | E5: 7
A6: Aydınlatma | B6: ='2 · Detay metraj'!G11+'2 · Detay metraj'!G12+'2 · Detay metraj'!G13+'2 · Detay metraj'!G14+'2 · Detay metraj'!G15+'2 · Detay metraj'!G16+'2 · Detay metraj'!G17 | C6: ='2 · Detay metraj'!H11+'2 · Detay metraj'!H12+'2 · Detay metraj'!H13+'2 · Detay metraj'!H14+'2 · Detay metraj'!H15+'2 · Detay metraj'!H16+'2 · Detay metraj'!H17 | D6: ='2 · Detay metraj'!I11+'2 · Detay metraj'!I12+'2 · Detay metraj'!I13+'2 · Detay metraj'!I14+'2 · Detay metraj'!I15+'2 · Detay metraj'!I16+'2 · Detay metraj'!I17 | E6: 7
A7: Priz ve kuvvet | B7: ='2 · Detay metraj'!G18+'2 · Detay metraj'!G19+'2 · Detay metraj'!G20+'2 · Detay metraj'!G21+'2 · Detay metraj'!G22+'2 · Detay metraj'!G23+'2 · Detay metraj'!G24 | C7: ='2 · Detay metraj'!H18+'2 · Detay metraj'!H19+'2 · Detay metraj'!H20+'2 · Detay metraj'!H21+'2 · Detay metraj'!H22+'2 · Detay metraj'!H23+'2 · Detay metraj'!H24 | D7: ='2 · Detay metraj'!I18+'2 · Detay metraj'!I19+'2 · Detay metraj'!I20+'2 · Detay metraj'!I21+'2 · Detay metraj'!I22+'2 · Detay metraj'!I23+'2 · Detay metraj'!I24 | E7: 7
A8: Zayıf akım | B8: ='2 · Detay metraj'!G25+'2 · Detay metraj'!G26+'2 · Detay metraj'!G27+'2 · Detay metraj'!G28+'2 · Detay metraj'!G29+'2 · Detay metraj'!G30+'2 · Detay metraj'!G31+'2 · Detay metraj'!G32+'2 · Detay metraj'!G33+'2 · Detay metraj'!G34+'2 · Detay metraj'!G35 | C8: ='2 · Detay metraj'!H25+'2 · Detay metraj'!H26+'2 · Detay metraj'!H27+'2 · Detay metraj'!H28+'2 · Detay metraj'!H29+'2 · Detay metraj'!H30+'2 · Detay metraj'!H31+'2 · Detay metraj'!H32+'2 · Detay metraj'!H33+'2 · Detay metraj'!H34+'2 · Detay metraj'!H35 | D8: ='2 · Detay metraj'!I25+'2 · Detay metraj'!I26+'2 · Detay metraj'!I27+'2 · Detay metraj'!I28+'2 · Detay metraj'!I29+'2 · Detay metraj'!I30+'2 · Detay metraj'!I31+'2 · Detay metraj'!I32+'2 · Detay metraj'!I33+'2 · Detay metraj'!I34+'2 · Detay metraj'!I35 | E8: 11
A9: Topraklama | B9: ='2 · Detay metraj'!G36+'2 · Detay metraj'!G37+'2 · Detay metraj'!G38+'2 · Detay metraj'!G39 | C9: ='2 · Detay metraj'!H36+'2 · Detay metraj'!H37+'2 · Detay metraj'!H38+'2 · Detay metraj'!H39 | D9: ='2 · Detay metraj'!I36+'2 · Detay metraj'!I37+'2 · Detay metraj'!I38+'2 · Detay metraj'!I39 | E9: 4
A10: ELEKTRIK İMALAT TOPLAMI | B10: =SUM(B5:B9) | C10: =SUM(C5:C9) | D10: =SUM(D5:D9) | E10: 36
A12: m² başına (net iç alan 103,78 m²) | B12: =B10/103.78 | C12: =C10/103.78 | D12: =D10/103.78
A14: ANA DOSYA İLE İLİŞKİ
A15: Bu dosyadaki pozlar, ana BoQ'daki 'ELEKTRİK' grubunun birebir aynısıdır.
A16: Ana dosya: output/Gym_Maliyet_BoQ.xlsx — 2 · Detay metraj sayfası

Sheet 2 · Detay metraj
A1: ELEKTRIK — DETAY METRAJ VE KEŞİF
A2: MALTEPE / İDEALTEPE — MOBİLYA MAĞAZASI → FONKSİYONEL ANTRENMAN STÜDYOSU · Rev H · 17 Eylül 2026 · Fiyat referansı: Eylül 2026 · Aqua Florya / Saltbae kesin hakedişi (Mayıs 2025) birim fiyatları ×1,40 eskalasyonla · Birim fiyat sütununu (F) doldurun, tutarlar kendiliğinden hesaplanır
A3: Poz No | B3: Sistem | C3: Tanım | D3: Birim | E3: Miktar | F3: Birim fiyat (TL) | G3: Tutar (TL) | H3: Referans düşük (TL) | I3: Referans yüksek (TL)
A4: 05.01 | B4: Ana dağıtım | C4: Ana dağıtım panosu — sıva üstü metal, 36 modül, montajlı | D4: adet | E4: 1 | G4: =E4*F4*1 | H4: 22000 | I4: 37000
A5: 05.02 | B5: Ana dağıtım | C5: Ana kesici 3×40 A, C eğrisi | D5: adet | E5: 1 | G5: =E5*F5*1 | H5: 3200 | I5: 5400
A6: 05.03 | B6: Ana dağıtım | C6: Kaçak akım rölesi 4×40 A / 30 mA (genel + ıslak hacim ayrı) | D6: adet | E6: 2 | G6: =E6*F6*1 | H6: 8400 | I6: 14000
A7: 05.04 | B7: Ana dağıtım | C7: Otomatik sigorta (1×6 / 1×10 / 1×16 / 1×32 A) | D7: adet | E7: 22 | G7: =E7*F7*1 | H7: 13640 | I7: 23100
A8: 05.05 | B8: Ana dağıtım | C8: Parafudr Tip 2 (aşırı gerilim koruma) | D8: adet | E8: 1 | G8: =E8*F8*1 | H8: 6800 | I8: 11500
A9: 05.06 | B9: Ana dağıtım | C9: NYY kolon hattı 5×10 mm² — sayaçtan panoya | D9: m | E9: 22 | G9: =E9*F9*1 | H9: 17160 | I9: 28600
A10: 05.07 | B10: Ana dağıtım | C10: Pano etiketleme, tek hat şeması çerçevesi ve fonksiyon testi | D10: götürü | E10: 1 | G10: =E10*F10*1 | H10: 6500 | I10: 11000
A11: 05.10 | B11: Aydınlatma | C11: Lineer LED armatür 40 W / 4400 lm, 1.200 mm (montaj dahil) | D11: adet | E11: 15 | G11: =E11*F11*1 | H11: 21000 | I11: 39000
A12: 05.11 | B12: Aydınlatma | C12: IP44 downlight 18 W / 1800 lm — ıslak hacim ve soyunma | D12: adet | E12: 6 | G12: =E12*F12*1 | H12: 5100 | I12: 9300
A13: 05.12 | B13: Aydınlatma | C13: Acil aydınlatma armatürü — 3 saat bataryalı | D13: adet | E13: 5 | G13: =E13*F13*1 | H13: 6250 | I13: 11000
A14: 05.13 | B14: Aydınlatma | C14: Acil çıkış yönlendirme armatürü | D14: adet | E14: 3 | G14: =E14*F14*1 | H14: 3450 | I14: 5850
A15: 05.14 | B15: Aydınlatma | C15: Aydınlatma linyesi NHXMH 3×1,5 mm² — spiral boru ve işçilik dâhil | D15: m | E15: 42 | G15: =E15*F15*1 | H15: 4620 | I15: 7770
... A39: 05.48 | B39: Topraklama | C39: Topraklama direnci ölçümü, izolasyon testi ve rapor | D39: götürü | E39: 1 | G39: =E39*F39*1 | H39: 7500 | I39: 13000
C41: ELEKTRIK İMALAT TOPLAMI | G41: =SUM(G4:G39) | H41: =SUM(H4:H39) | I41: =SUM(I4:I39)

Sheet 3 · Sistem verileri
A1: ELEKTRİK SİSTEM VERİLERİ
A2: Linye tablosu · faz dengesi · yük özeti
A4: GÜÇ ÖZETİ
A5: Toplam bağlı güç | B5: 20.59 | C5: kW
A6: Talep gücü (eşzamanlılık) | B6: 14.63 | C6: kW
A7: Faz dengesizliği | B7: 1 | C7: %
A8: Ana kesici | B8: 32 | C8: ×3 A
A9: Linye adedi | B9: 22 | C9: adet
A11: FAZ YÜKLERİ
A12: Faz L1 | B12: 4.86 | C12: kW
A13: Faz L2 | B13: 4.91 | C13: kW
A14: Faz L3 | B14: 4.87 | C14: kW
A15: Akım L1 | B15: 23 | C15: A
A16: Akım L2 | B16: 23.2 | C16: A
A17: Akım L3 | B17: 23 | C17: A
A19: CİHAZ ADETLERİ
A20: Lineer LED armatür | B20: 15 | C20: adet
A21: IP44 downlight | B21: 6 | C21: adet
A22: İkili topraklı priz | B22: 20 | C22: adet
A23: IP44 priz | B23: 2 | C23: adet
A24: IP kamera | B24: 5 | C24: adet
A25: Tavan hoparlörü | B25: 6 | C25: adet
A26: Duman dedektörü | B26: 6 | C26: adet
A28: KABLO METRAJI
A29: Aydınlatma linyesi 3×1,5 | B29: 42 | C29: m
A30: Priz/kuvvet linyesi 3×2,5 | B30: 391 | C30: m
A31: Zayıf akım kablolaması | B31: 212 | C31: m
A32: Kolon hattı NYY 5×10 | B32: 22 | C32: m
A34: LİNYE TABLOSU
A35: Linye | B35: Tanım | C35: Koruma / kesit | D35: Faz · bağlı kW · talep kW
A36: L1 | B36: Aydınlatma — arena / serbest ağırlık | C36: 1×10 A · 3×2,5 mm² | D36: L2 · 0.28 · 0.28
A37: L2 | B37: Aydınlatma — fonksiyonel / kardiyo | C37: 1×10 A · 3×2,5 mm² | D37: L3 · 0.12 · 0.12
A38: L3 | B38: Aydınlatma — dinlenme salonu | C38: 1×10 A · 3×2,5 mm² | D38: L1 · 0.12 · 0.12
A39: L4 | B39: Aydınlatma — giriş / banko | C39: 1×10 A · 3×2,5 mm² | D39: L3 · 0.08 · 0.08
A40: L5 | B40: Aydınlatma — ıslak hacim (IP44) | C40: 1×10 A · 3×2,5 mm² | D40: L1 · 0.11 · 0.07
A41: L6 | B41: Acil aydınlatma ve yönlendirme | C41: 1×6 A · 3×2,5 mm² | D41: L2 · 0.06 · 0.06
A42: P1 | B42: Priz — salon kuzey (PR12–PR16, PR1) | C42: 1×16 A · 3×2,5 mm² | D42: L1 · 0.90 · 0.45
A43: P2 | B43: Priz — salon güney (PR5–PR9) | C43: 1×16 A · 3×2,5 mm² | D43: L3 · 0.75 · 0.38
A44: P6 | B44: Priz — salon batı ve doğu (PR2–PR4, PR10, PR11) | C44: 1×16 A · 3×2,5 mm² | D44: L1 · 0.75 · 0.38
A45: P3 | B45: Priz — banko, POS, veri | C45: 1×16 A · 3×2,5 mm² | D45: L2 · 1.00 · 0.70
...

Sheet 4 · Varsayımlar
A1: VARSAYIMLAR VE DOĞRULANACAKLAR
A2: Bu değerler ölçülmemiştir
A3: Parametre | B3: Değer | C3: Not
A4: Tavan yüksekliği | B4: 3,20 m | C4: VARSAYIM — iç hacim, kanal güzergâhı ve armatür adedinin girdisi
A5: Geometri doğruluğu | B5: ±%3 | C5: Raster paftadan vektörleştirme — DXF (R2010) ile kesinleştirilmeli
A6: Net iç kullanım alanı | B6: 103,78 m² | C6: Pafta m² etiketlerinden kalibre
A7: Mevcut pano gücü / trifaze | B7: BİLİNMİYOR | C7: Talep 17,03 kW — 3×32 A gerekir; yetersizse 3–8 hafta güç artırımı
A8: Temel topraklaması | B8: Yok varsayıldı | C8: Varsa 05.45 pozu iptal edilir
A9: Kablo metrajları | B9: Güzergâh uzunluğundan | C9: Yaklaşık değer — DXF sonrası kesinleşir
A10: Sıcak su çözümü | B10: 2 × 6 kW ani ısıtıcı | C10: Boylere çevrilirse talep gücü ≈5 kW düşer, 3×25 A yeterli olur
A11: Kamera kapsamı | B11: Soyunma ve WC HARİÇ | C11: Kişisel verilerin korunması — kapsam dışı bırakılmıştır
