Workbook

Sheet 1 · Özet
A1: MALTEPE / İDEALTEPE — GYM DÖNÜŞÜMÜ · MALİYET ÖZETİ
A2: Rev G · 17 Eylül 2026 · Eylül 2026 · Aqua Florya / Saltbae kesin hakedişi (Mayıs 2025) birim fiyatları ×1,40 eskalasyonla · Ekipman işverence temin edilmiştir, bütçe dışıdır.
A4: SENARYO SEÇİMİ | B4: ÖNERİLEN | C4: Açılır listeden seçin — tüm toplamlar anında yeniden hesaplanır | D4: ISLAK HACİM | E4: A | F4: A: zemin yükseltme · B: pompa
A6: Maliyet başlığı | B6: Teklif tutarı (TL) | C6: Referans düşük (TL) | D6: Referans yüksek (TL) | E6: Poz adedi | F6: Pay (%)
A7: YIKIM · SÖKÜM | B7: ='2 · Detay metraj'!G4+'2 · Detay metraj'!G5+'2 · Detay metraj'!G6+'2 · Detay metraj'!G7 | C7: ='2 · Detay metraj'!H4+'2 · Detay metraj'!H5+'2 · Detay metraj'!H6+'2 · Detay metraj'!H7 | D7: ='2 · Detay metraj'!I4+'2 · Detay metraj'!I5+'2 · Detay metraj'!I6+'2 · Detay metraj'!I7 | E7: 4 | F7: =IFERROR((C7+D7)/2/(($C$18+$D$18)/2),0)
A8: DUVAR · ALÇIPAN | B8: ='2 · Detay metraj'!G8+'2 · Detay metraj'!G9+'2 · Detay metraj'!G10+'2 · Detay metraj'!G11 | C8: ='2 · Detay metraj'!H8+'2 · Detay metraj'!H9+'2 · Detay metraj'!H10+'2 · Detay metraj'!H11 | D8: ='2 · Detay metraj'!I8+'2 · Detay metraj'!I9+'2 · Detay metraj'!I10+'2 · Detay metraj'!I11 | E8: 4 | F8: =IFERROR((C8+D8)/2/(($C$18+$D$18)/2),0)
A9: ISLAK HACİM | B9: ='2 · Detay metraj'!G12+'2 · Detay metraj'!G13+'2 · Detay metraj'!G14+'2 · Detay metraj'!G15+'2 · Detay metraj'!G16+'2 · Detay metraj'!G17+'2 · Detay metraj'!G18 | C9: ='2 · Detay metraj'!H12+'2 · Detay metraj'!H13+'2 · Detay metraj'!H14+'2 · Detay metraj'!H15+'2 · Detay metraj'!H16+'2 · Detay metraj'!H17+'2 · Detay metraj'!H18 | D9: ='2 · Detay metraj'!I12+'2 · Detay metraj'!I13+'2 · Detay metraj'!I14+'2 · Detay metraj'!I15+'2 · Detay metraj'!I16+'2 · Detay metraj'!I17+'2 · Detay metraj'!I18 | E9: 7 | F9: =IFERROR((C9+D9)/2/(($C$18+$D$18)/2),0)
A10: ZEMİN | B10: ='2 · Detay metraj'!G19+'2 · Detay metraj'!G20+'2 · Detay metraj'!G21+'2 · Detay metraj'!G22+'2 · Detay metraj'!G23 | C10: ='2 · Detay metraj'!H19+'2 · Detay metraj'!H20+'2 · Detay metraj'!H21+'2 · Detay metraj'!H22+'2 · Detay metraj'!H23 | D10: ='2 · Detay metraj'!I19+'2 · Detay metraj'!I20+'2 · Detay metraj'!I21+'2 · Detay metraj'!I22+'2 · Detay metraj'!I23 | E10: 5 | F10: =IFERROR((C10+D10)/2/(($C$18+$D$18)/2),0)
A11: ELEKTRİK | B11: ='2 · Detay metraj'!G79+'2 · Detay metraj'!G80+'2 · Detay metraj'!G81+'2 · Detay metraj'!G82+'2 · Detay metraj'!G83+'2 · Detay metraj'!G84+'2 · Detay metraj'!G85+'2 · Detay metraj'!G86+'2 · Detay metraj'!G87+'2 · Detay metraj'!G88+'2 · Detay metraj'!G89+'2 · Detay metraj'!G90+'2 · Detay metraj'!G91+'2 · Detay metraj'!G92+'2 · Detay metraj'!G93+'2 · Detay metraj'!G94+'2 · Detay metraj'!G95+'2 · Detay metraj'!G96+'2 · Detay metraj'!G97+'2 · Detay metraj'!G98+'2 · Detay metraj'!G99+'2 · Detay metraj'!G100+'2 · Detay metraj'!G101+'2 · Detay metraj'!G102+'2 · Detay metraj'!G103+'2 · Detay metraj'!G104+'2 · Detay metraj'!G105+'2 · Detay metraj'!G106+'2 · Detay metraj'!G107+'2 · Detay metraj'!G108+'2 · Detay metraj'!G109+'2 · Detay metraj'!G110+'2 · Detay metraj'!G111+'2 · Detay metraj'!G112+'2 · Detay metraj'!G113+'2 · Detay metraj'!G114 | C11: ='2 · Detay metraj'!H79+'2 · Detay metraj'!H80+'2 · Detay metraj'!H81+'2 · Detay metraj'!H82+'2 · Detay metraj'!H83+'2 · Detay metraj'!H84+'2 · Detay metraj'!H85+'2 · Detay metraj'!H86+'2 · Detay metraj'!H87+'2 · Detay metraj'!H88+'2 · Detay metraj'!H89+'2 · Detay metraj'!H90+'2 · Detay metraj'!H91+'2 · Detay metraj'!H92+'2 · Detay metraj'!H93+'2 · Detay metraj'!H94+'2 · Detay metraj'!H95+'2 · Detay metraj'!H96+'2 · Detay metraj'!H97+'2 · Detay metraj'!H98+'2 · Detay metraj'!H99+'2 · Detay metraj'!H100+'2 · Detay metraj'!H101+'2 · Detay metraj'!H102+'2 · Detay metraj'!H103+'2 · Detay metraj'!H104+'2 · Detay metraj'!H105+'2 · Detay metraj'!H106+'2 · Detay metraj'!H107+'2 · Detay metraj'!H108+'2 · Detay metraj'!H109+'2 · Detay metraj'!H110+'2 · Detay metraj'!H111+'2 · Detay metraj'!H112+'2 · Detay metraj'!H113+'2 · Detay metraj'!H114 | D11: ='2 · Detay metraj'!I79+'2 · Detay metraj'!I80+'2 · Detay metraj'!I81+'2 · Detay metraj'!I82+'2 · Detay metraj'!I83+'2 · Detay metraj'!I84+'2 · Detay metraj'!I85+'2 · Detay metraj'!I86+'2 · Detay metraj'!I87+'2 · Detay metraj'!I88+'2 · Detay metraj'!I89+'2 · Detay metraj'!I90+'2 · Detay metraj'!I91+'2 · Detay metraj'!I92+'2 · Detay metraj'!I93+'2 · Detay metraj'!I94+'2 · Detay metraj'!I95+'2 · Detay metraj'!I96+'2 · Detay metraj'!I97+'2 · Detay metraj'!I98+'2 · Detay metraj'!I99+'2 · Detay metraj'!I100+'2 · Detay metraj'!I101+'2 · Detay metraj'!I102+'2 · Detay metraj'!I103+'2 · Detay metraj'!I104+'2 · Detay metraj'!I105+'2 · Detay metraj'!I106+'2 · Detay metraj'!I107+'2 · Detay metraj'!I108+'2 · Detay metraj'!I109+'2 · Detay metraj'!I110+'2 · Detay metraj'!I111+'2 · Detay metraj'!I112+'2 · Detay metraj'!I113+'2 · Detay metraj'!I114 | E11: 36 | F11: =IFERROR((C11+D11)/2/(($C$18+$D$18)/2),0)
A12: MEKANİK | B12: ='2 · Detay metraj'!G42+'2 · Detay metraj'!G43+'2 · Detay metraj'!G44+'2 · Detay metraj'!G45+'2 · Detay metraj'!G46+'2 · Detay metraj'!G47+'2 · Detay metraj'!G48+'2 · Detay metraj'!G49+'2 · Detay metraj'!G50+'2 · Detay metraj'!G51+'2 · Detay metraj'!G52+'2 · Detay metraj'!G53+'2 · Detay metraj'!G54+'2 · Detay metraj'!G55+'2 · Detay metraj'!G56+'2 · Detay metraj'!G57+'2 · Detay metraj'!G58+'2 · Detay metraj'!G59+'2 · Detay metraj'!G60+'2 · Detay metraj'!G61+'2 · Detay metraj'!G62+'2 · Detay metraj'!G63+'2 · Detay metraj'!G64+'2 · Detay metraj'!G65+'2 · Detay metraj'!G66+'2 · Detay metraj'!G67+'2 · Detay metraj'!G68+'2 · Detay metraj'!G69+'2 · Detay metraj'!G70+'2 · Detay metraj'!G71+'2 · Detay metraj'!G72+'2 · Detay metraj'!G73+'2 · Detay metraj'!G74+'2 · Detay metraj'!G75+'2 · Detay metraj'!G76+'2 · Detay metraj'!G77+'2 · Detay metraj'!G78 | C12: ='2 · Detay metraj'!H42+'2 · Detay metraj'!H43+'2 · Detay metraj'!H44+'2 · Detay metraj'!H45+'2 · Detay metraj'!H46+'2 · Detay metraj'!H47+'2 · Detay metraj'!H48+'2 · Detay metraj'!H49+'2 · Detay metraj'!H50+'2 · Detay metraj'!H51+'2 · Detay metraj'!H52+'2 · Detay metraj'!H53+'2 · Detay metraj'!H54+'2 · Detay metraj'!H55+'2 · Detay metraj'!H56+'2 · Detay metraj'!H57+'2 · Detay metraj'!H58+'2 · Detay metraj'!H59+'2 · Detay metraj'!H60+'2 · Detay metraj'!H61+'2 · Detay metraj'!H62+'2 · Detay metraj'!H63+'2 · Detay metraj'!H64+'2 · Detay metraj'!H65+'2 · Detay metraj'!H66+'2 · Detay metraj'!H67+'2 · Detay metraj'!H68+'2 · Detay metraj'!H69+'2 · Detay metraj'!H70+'2 · Detay metraj'!H71+'2 · Detay metraj'!H72+'2 · Detay metraj'!H73+'2 · Detay metraj'!H74+'2 · Detay metraj'!H75+'2 · Detay metraj'!H76+'2 · Detay metraj'!H77+'2 · Detay metraj'!H78 | D12: ='2 · Detay metraj'!I42+'2 · Detay metraj'!I43+'2 · Detay metraj'!I44+'2 · Detay metraj'!I45+'2 · Detay metraj'!I46+'2 · Detay metraj'!I47+'2 · Detay metraj'!I48+'2 · Detay metraj'!I49+'2 · Detay metraj'!I50+'2 · Detay metraj'!I51+'2 · Detay metraj'!I52+'2 · Detay metraj'!I53+'2 · Detay metraj'!I54+'2 · Detay metraj'!I55+'2 · Detay metraj'!I56+'2 · Detay metraj'!I57+'2 · Detay metraj'!I58+'2 · Detay metraj'!I59+'2 · Detay metraj'!I60+'2 · Detay metraj'!I61+'2 · Detay metraj'!I62+'2 · Detay metraj'!I63+'2 · Detay metraj'!I64+'2 · Detay metraj'!I65+'2 · Detay metraj'!I66+'2 · Detay metraj'!I67+'2 · Detay metraj'!I68+'2 · Detay metraj'!I69+'2 · Detay metraj'!I70+'2 · Detay metraj'!I71+'2 · Detay metraj'!I72+'2 · Detay metraj'!I73+'2 · Detay metraj'!I74+'2 · Detay metraj'!I75+'2 · Detay metraj'!I76+'2 · Detay metraj'!I77+'2 · Detay metraj'!I78 | E12: 37 | F12: =IFERROR((C12+D12)/2/(($C$18+$D$18)/2),0)
A13: BOYA · DEKOR | B13: ='2 · Detay metraj'!G24+'2 · Detay metraj'!G25+'2 · Detay metraj'!G26+'2 · Detay metraj'!G27 | C13: ='2 · Detay metraj'!H24+'2 · Detay metraj'!H25+'2 · Detay metraj'!H26+'2 · Detay metraj'!H27 | D13: ='2 · Detay metraj'!I24+'2 · Detay metraj'!I25+'2 · Detay metraj'!I26+'2 · Detay metraj'!I27 | E13: 4 | F13: =IFERROR((C13+D13)/2/(($C$18+$D$18)/2),0)
A14: MARANGOZ | B14: ='2 · Detay metraj'!G28+'2 · Detay metraj'!G29+'2 · Detay metraj'!G30 | C14: ='2 · Detay metraj'!H28+'2 · Detay metraj'!H29+'2 · Detay metraj'!H30 | D14: ='2 · Detay metraj'!I28+'2 · Detay metraj'!I29+'2 · Detay metraj'!I30 | E14: 3 | F14: =IFERROR((C14+D14)/2/(($C$18+$D$18)/2),0)
A15: DOĞRAMA | B15: ='2 · Detay metraj'!G37+'2 · Detay metraj'!G38+'2 · Detay metraj'!G39+'2 · Detay metraj'!G40+'2 · Detay metraj'!G41 | C15: ='2 · Detay metraj'!H37+'2 · Detay metraj'!H38+'2 · Detay metraj'!H39+'2 · Detay metraj'!H40+'2 · Detay metraj'!H41 | D15: ='2 · Detay metraj'!I37+'2 · Detay metraj'!I38+'2 · Detay metraj'!I39+'2 · Detay metraj'!I40+'2 · Detay metraj'!I41 | E15: 5 | F15: =IFERROR((C15+D15)/2/(($C$18+$D$18)/2),0)
A16: YANGIN · GÜVENLİK | B16: ='2 · Detay metraj'!G31+'2 · Detay metraj'!G32+'2 · Detay metraj'!G33+'2 · Detay metraj'!G34 | C16: ='2 · Detay metraj'!H31+'2 · Detay metraj'!H32+'2 · Detay metraj'!H33+'2 · Detay metraj'!H34 | D16: ='2 · Detay metraj'!I31+'2 · Detay metraj'!I32+'2 · Detay metraj'!I33+'2 · Detay metraj'!I34 | E16: 4 | F16: =IFERROR((C16+D16)/2/(($C$18+$D$18)/2),0)
A17: TABELA · DIŞ | B17: ='2 · Detay metraj'!G35+'2 · Detay metraj'!G36 | C17: ='2 · Detay metraj'!H35+'2 · Detay metraj'!H36 | D17: ='2 · Detay metraj'!I35+'2 · Detay metraj'!I36 | E17: 2 | F17: =IFERROR((C17+D17)/2/(($C$18+$D$18)/2),0)
A18: İMALAT ARA TOPLAMI | B18: =SUM(B7:B17) | C18: =SUM(C7:C17) | D18: =SUM(D7:D17) | E18: 111 | F18: 1
A19: Şantiye genel giderleri (%12) | B19: =B18*0.12 | C19: =C18*0.12 | D19: =D18*0.12
A20: Beklenmedik giderler (%15) | B20: =(B18+B19)*0.15 | C20: =(C18+C19)*0.15 | D20: =(D18+D19)*0.15
A21: GENEL TOPLAM | B21: =B18+B19+B20 | C21: =C18+C19+C20 | D21: =D18+D19+D20
A23: m² başına (net iç alan) | B23: =B21/103.78 | C23: =C21/103.78 | D23: =D21/103.78
A25: AÇILIŞ ÖNCESİ NAKİT İHTİYACI
A26: Tadilat (genel toplam) | B26: =B21 | C26: =C21 | D26: =D21
A27: Ruhsat · harç · GSİM tescil · itfaiye · sağlık raporu | C27: 85000 | D27: 175000
A28: Proje / mimari onaylı 1/100 vaziyet planı · müşavirlik | C28: 45000 | D28: 95000
A29: İlk 3 ay kira | C29: 84000 | D29: 156000
A30: Depozito (3 ay) | C30: 84000 | D30: 156000
A31: Personel (açılış öncesi 2 ay · 2 kişi) | C31: 160000 | D31: 280000
A32: Pazarlama · açılış kampanyası · dijital | C32: 95000 | D32: 210000
A33: Yazılım (üyelik/POS), sarf, ilk stok | C33: 55000 | D33: 120000
A34: TOPLAM AÇILIŞ ÖNCESİ NAKİT | B34: =SUM(B26:B33) | C34: =SUM(C26:C33) | D34: =SUM(D26:D33)

Sheet 2 · Detay metraj
A1: DETAY METRAJ VE KEŞİF — birim fiyat sütunlarını doldurun, tutarlar kendiliğinden hesaplanır
A2: MALTEPE / İDEALTEPE — MOBİLYA MAĞAZASI → FONKSİYONEL ANTRENMAN STÜDYOSU · Rev G · 17 Eylül 2026 · Fiyat referansı: Eylül 2026 · Aqua Florya / Saltbae kesin hakedişi (Mayıs 2025) birim fiyatları ×1,40 eskalasyonla · Net iç alan 103.78 m²
A3: Poz No | B3: Grup | C3: Tanım | D3: Birim | E3: Miktar | F3: Birim fiyat (TL) | G3: Tutar (TL) | H3: Referans düşük (TL) | I3: Referans yüksek (TL) | J3: Senaryo | K3: Dâhil
A4: 01.01 | B4: YIKIM · SÖKÜM | C4: Mobilya mağazası raf/vitrin/tezgâh sökümü ve tasnifi | D4: m² | E4: 103.78 | G4: =E4*F4*K4 | H4: =35285*K4 | I4: =60192*K4 | J4: M | K4: 1
A5: 01.02 | B5: YIKIM · SÖKÜM | C5: Mevcut zemin kaplaması sökümü ve şap tesviyesi | D5: m² | E5: 103.78 | G5: =E5*F5*K5 | H5: =43588*K5 | I5: =67457*K5 | J5: M | K5: 1
A6: 01.03 | B6: YIKIM · SÖKÜM | C6: Islak hacim mevcut seramik + vitrifiye sökümü | D6: m² | E6: 16.73 | G6: =E6*F6*K6 | H6: =10373*K6 | I6: =15894*K6 | J6: M | K6: 1
A7: 01.04 | B7: YIKIM · SÖKÜM | C7: Moloz yükleme, indirme ve nakliye (konteyner) | D7: götürü | E7: 1 | G7: =E7*F7*K7 | H7: =48000*K7 | I7: =75000*K7 | J7: M | K7: 1
A8: 02.01 | B8: DUVAR · ALÇIPAN | C8: Alçıpan bölme duvar — 100 mm, çift kat, taşyünü dolgulu | D8: m² | E8: 44.6 | G8: =E8*F8*K8 | H8: =138260*K8 | I8: =173940*K8 | J8: M | K8: 1
A9: 02.02 | B9: DUVAR · ALÇIPAN | C9: Islak hacim bölmelerinde yeşil alçıpan / betopan yükseltmesi | D9: m² | E9: 20.1 | G9: =E9*F9*K9 | H9: =7035*K9 | I9: =10452*K9 | J9: M | K9: 1
A10: 02.03 | B10: DUVAR · ALÇIPAN | C10: Mevcut duvar tamiri, saten alçı ve yüzey hazırlığı | D10: m² | E10: 129.3 | G10: =E10*F10*K10 | H10: =49134*K10 | I10: =72408*K10 | J10: M | K10: 1
A11: 02.04 | B11: DUVAR · ALÇIPAN | C11: Akustik asma tavan adası (arena üzeri) — 12 m² | D11: m² | E11: 12 | G11: =E11*F11*K11 | H11: =31200*K11 | I11: =50400*K11 | J11: O | K11: =IF('1 · Özet'!$B$4="ÖNERİLEN",1,0)
A12: 03.02 | B12: ISLAK HACİM | C12: Su yalıtımı — çift bileşenli, dönüş 30 cm | D12: m² | E12: 24.3 | G12: =E12*F12*K12 | H12: =19440*K12 | I12: =26730*K12 | J12: M | K12: 1
A13: 03.03 | B13: ISLAK HACİM | C13: Zemin seramiği R11 kaymaz (malzeme + işçilik) | D13: m² | E13: 16.73 | G13: =E13*F13*K13 | H13: =28943*K13 | I13: =41825*K13 | J13: M | K13: 1
A14: 03.04 | B14: ISLAK HACİM | C14: Duvar fayansı h=2,20 m (malzeme + işçilik) | D14: m² | E14: 55.7 | G14: =E14*F14*K14 | H14: =99982*K14 | I14: =147605*K14 | J14: M | K14: 1
A15: 03.05 | B15: ISLAK HACİM | C15: Vitrifiye seti — 2 klozet, 2 lavabo, armatürler | D15: takım | E15: 2 | G15: =E15*F15*K15 | H15: =52000*K15 | I15: =96000*K15 | J15: M | K15: 1
A16: 03.06 | B16: ISLAK HACİM | C16: Duş teknesi + cam duşakabin (2 adet) | D16: adet | E16: 2 | G16: =E16*F16*K16 | H16: =44000*K16 | I16: =80000*K16 | J16: M | K16: 1
A17: 03.08 | B17: ISLAK HACİM | C17: SEÇENEK A — ıslak hacim zemini 15–20 cm yükseltme (hafif dolgu + şap + basamak/rampa) | D17: m² | E17: 16.73 | G17: =E17*F17*K17 | H17: =23422*K17 | I17: =38479*K17 | J17: A | K17: =IF('1 · Özet'!$E$4="A",1,0)
A18: 03.09 | B18: ISLAK HACİM | C18: SEÇENEK B — öğütücülü gri su / atık su pompası (2 ünite + hat) | D18: takım | E18: 1 | G18: =E18*F18*K18 | H18: =95000*K18 | I18: =170000*K18 | J18: B | K18: =IF('1 · Özet'!$E$4="B",1,0)
A19: 04.01 | B19: ZEMİN | C19: Kauçuk karo 40 mm — arena / serbest ağırlık | D19: m² | E19: 31.76 | G19: =E19*F19*K19 | H19: =87340*K19 | I19: =124499*K19 | J19: M | K19: 1
A20: 04.02 | B20: ZEMİN | C20: Titreşim matı 10 mm (arena altı — üst katta konut varsayımı) | D20: m² | E20: 31.76 | G20: =E20*F20*K20 | H20: =26361*K20 | I20: =40018*K20 | J20: O | K20: =IF('1 · Özet'!$B$4="ÖNERİLEN",1,0)
A21: 04.03 | B21: ZEMİN | C21: Kauçuk karo 20 mm — fonksiyonel / kardiyo | D21: m² | E21: 22.31 | G21: =E21*F21*K21 | H21: =36812*K21 | I21: =53544*K21 | J21: M | K21: 1
A22: 04.04 | B22: ZEMİN | C22: LVT / laminat parke — dinlenme + giriş / banko | D22: m² | E22: 32.98 | G22: =E22*F22*K22 | H22: =45183*K22 | I22: =69918*K22 | J22: M | K22: 1
A23: 04.05 | B23: ZEMİN | C23: Süpürgelik, geçiş profilleri, eşikler | D23: m | E23: 71.5 | G23: =E23*F23*K23 | H23: =25025*K23 | I23: =39325*K23 | J23: M | K23: 1
A24: 07.01 | B24: BOYA · DEKOR | C24: Silinebilir mat duvar boyası (astar + 2 kat) | D24: m² | E24: 129.3 | G24: =E24*F24*K24 | H24: =49781*K24 | I24: =78873*K24 | J24: M | K24: 1
A25: 07.02 | B25: BOYA · DEKOR | C25: Tavan boyası / açık tavan siyah boya (endüstriyel) | D25: m² | E25: 103.78 | G25: =E25*F25*K25 | H25: =42031*K25 | I25: =65381*K25 | J25: M | K25: 1
A26: 07.03 | B26: BOYA · DEKOR | C26: Ayna — arena ve fonksiyonel alan (6 mm, montaj dahil) | D26: m² | E26: 14 | G26: =E26*F26*K26 | H26: =64400*K26 | I26: =103600*K26 | J26: O | K26: =IF('1 · Özet'!$B$4="ÖNERİLEN",1,0)
A27: 07.04 | B27: BOYA · DEKOR | C27: Duvar grafiği / marka uygulaması | D27: götürü | E27: 1 | G27: =E27*F27*K27 | H27: =48000*K27 | I27: =95000*K27 | J27: O | K27: =IF('1 · Özet'!$B$4="ÖNERİLEN",1,0)
A28: 08.01 | B28: MARANGOZ | C28: Resepsiyon bankosu — 2,40 m, kompakt lamine tezgâh | D28: m | E28: 2.4 | G28: =E28*F28*K28 | H28: =62400*K28 | I28: =103200*K28 | J28: M | K28: 1
A29: 08.02 | B29: MARANGOZ | C29: Soyunma dolabı / askılık — 24 göz (2 blok) | D29: göz | E29: 24 | G29: =E29*F29*K29 | H29: =62400*K29 | I29: =105600*K29 | J29: M | K29: 1
A30: 08.03 | B30: MARANGOZ | C30: Oturma bankı (soyunma) + dinlenme mobilyası | D30: götürü | E30: 1 | G30: =E30*F30*K30 | H30: =48000*K30 | I30: =92000*K30 | J30: O | K30: =IF('1 · Özet'!$B$4="ÖNERİLEN",1,0)
A31: 09.01 | B31: YANGIN · GÜVENLİK | C31: 6 kg KKT yangın söndürücü + dolap + montaj | D31: adet | E31: 4 | G31: =E31*F31*K31 | H31: =18000*K31 | I31: =30400*K31 | J31: M | K31: 1
A32: 09.03 | B32: YANGIN · GÜVENLİK | C32: Keskin köşe / kolon darbe hafifletici kaplama | D32: m | E32: 18 | G32: =E32*F32*K32 | H32: =21600*K32 | I32: =37800*K32 | J32: M | K32: 1
A33: 09.04 | B33: YANGIN · GÜVENLİK | C33: Engelli erişimi — rampa, tutamak, kapı genişliği düzenlemesi | D33: götürü | E33: 1 | G33: =E33*F33*K33 | H33: =42000*K33 | I33: =90000*K33 | J33: M | K33: 1
A34: 09.05 | B34: YANGIN · GÜVENLİK | C34: İlk yardım dolabı, AED, acil çıkış donanımı | D34: takım | E34: 1 | G34: =E34*F34*K34 | H34: =34000*K34 | I34: =63000*K34 | J34: M | K34: 1
A35: 10.01 | B35: TABELA · DIŞ | C35: Işıklı kutu harf tabela + cephe folyo | D35: götürü | E35: 1 | G35: =E35*F35*K35 | H35: =68000*K35 | I35: =135000*K35 | J35: O | K35: =IF('1 · Özet'!$B$4="ÖNERİLEN",1,0)
A36: 10.02 | B36: TABELA · DIŞ | C36: Cephe doğrama temizlik / bakım, giriş kapısı revizyonu | D36: götürü | E36: 1 | G36: =E36*F36*K36 | H36: =50000*K36 | I36: =85000*K36 | J36: M | K36: 1
A37: 11.01 | B37: DOĞRAMA | C37: İç kapı K03 · K04 — panel kapı 90×210, kasa, pervaz ve donanım | D37: adet | E37: 2 | G37: =E37*F37*K37 | H37: =37000*K37 | I37: =58000*K37 | J37: M | K37: 1
A38: 11.02 | B38: DOĞRAMA | C38: WC kapısı K05 · K06 — tam WPC 70×200, alt menfezli | D38: adet | E38: 2 | G38: =E38*F38*K38 | H38: =30000*K38 | I38: =49000*K38 | J38: M | K38: 1
A39: 11.03 | B39: DOĞRAMA | C39: Duş kapağı K07 · K08 — 6 mm temperli cam 70×195 | D39: adet | E39: 2 | G39: =E39*F39*K39 | H39: =35000*K39 | I39: =56000*K39 | J39: M | K39: 1
A40: 11.04 | B40: DOĞRAMA | C40: Depo / teknik dolap kapağı K09 — havalandırma menfezli | D40: adet | E40: 1 | G40: =E40*F40*K40 | H40: =9000*K40 | I40: =15000*K40 | J40: M | K40: 1
...

Sheet 3 · Ekipman (işverence temin)
A1: EKİPMAN BİLGİ SAYFASI — BÜTÇE DIŞI
A2: Ekipman işverence satın alınmıştır; bu dosyadaki maliyet kalemlerine dâhil değildir. Marka/model listesi geldiğinde aşağıdaki sütunlar doldurulmalıdır.
A3: Kod | B3: Ekipman | C3: En (cm) | D3: Boy (cm) | E3: Yükseklik (m) | F3: Adet | G3: Footprint (m²) | H3: Marka / model (işveren dolduracak)
A4: A | B4: TRIMODE ARENA — altıgen ring, 4 sıra halat | C4: altıgen | D4: 10,60 m² | E4: 1.8 | F4: 1 | G4: 10.6
A5: B | B5: Çok fonksiyonlu kuvvet istasyonu (ağırlık takozlu) | C5: 244 | D5: 62 | E5: 2.1 | F5: 1 | G5: 1.51
A6: C | B6: Kablo çapraz / functional trainer | C6: 175 | D6: 232 | E6: 2.15 | F6: 1 | G6: 4.06
A7: D | B7: Dambıl rafı / sehpa | C7: 155 | D7: 39 | E7: 0.95 | F7: 2 | G7: 1.21
A8: E | B8: Kardiyo — kondisyon bisikleti | C8: 84 | D8: 150 | E8: 1.25 | F8: 1 | G8: 1.26
A9: F | B9: Koşu bandı | C9: 245 | D9: 74 | E9: 1.45 | F9: 2 | G9: 3.63
B10: TOPLAM FOOTPRINT | F10: =SUM(F4:F9) | G10: =SUM(G4:G9)
B12: Salon brüt alanı | G12: 87.05
B13: Serbest sirkülasyon / çalışma alanı | G13: =87.05-G10

Sheet 4 · Varsayımlar
A1: VARSAYIMLAR, METRAJ DAYANAĞI VE DOĞRULANACAKLAR
A3: Parametre | B3: Değer | C3: Birim | D3: Kaynak / varsayım notu
A4: Salon alanı | B4: 87.05 | C4: m² | D4: Alan Dağılımı paftası etiketi
A5: Erkek soyunma bloğu | B5: 8.24 | C5: m² | D5: Alan Dağılımı paftası etiketi
A6: Kadın soyunma bloğu | B6: 8.49 | C6: m² | D6: Alan Dağılımı paftası etiketi
A7: Net iç kullanım alanı | B7: 103.78 | C7: m² | D7: Toplam — tüm metrajın temeli
A8: Ön bahçe | B8: 24.39 | C8: m² | D8: Açık alan
A9: Arka bahçe | B9: 32.82 | C9: m² | D9: Açık alan
A10: Salon dış çevre uzunluğu | B10: 46.15 | C10: m | D10: Vektörleştirilmiş poligon
A11: Islak hacim blok çevresi | B11: 25.32 | C11: m | D11: Vektörleştirilmiş poligon
A12: Boyanacak / sıvalanacak duvar | B12: 129.3 | C12: m² | D12: Çevre × tavan − cephe doğraması
A13: Islak hacim duvar fayansı | B13: 55.7 | C13: m² | D13: Blok çevresi × 2,20 m
A14: Yeni alçıpan bölme | B14: 44.6 | C14: m² | D14: Blok içi bölme payı × tavan
A15: Armatür adedi | B15: 15 | C15: adet | D15: Lux hesabı — bakım 0,80 · verim 0,70 · 4400 lm
... A20: Beklenmedik pay | B20: 0.15 | C20: oran | D20: Islak hacim belirsizliği yüksek
A22: DOĞRULANACAK — bu değerler ölçülmemiştir
A23: Tavan yüksekliği | B23: 3.2 | C23: m | D23: VARSAYIM — yerinde doğrulanacak (mağaza tipik 3,0–3,6 m)
A24: Mevcut pis su kotu | B24: — | C24: cm | D24: BİLİNMİYOR — Seçenek A/B kararını belirler
A25: Elektrik pano gücü | B25: — | C25: kW | D25: BİLİNMİYOR — talep 12,1 kW
A26: Üst katta konut | B26: VAR | C26: E/H | D26: VARSAYIM (konservatif) — akustik kalemleri buna bağlı
A27: Doğalgaz bağlantısı | B27: — | C27: E/H | D27: Varsa sıcak su çözümü kombiye döner (poz 03.07)
A28: Geometri doğruluğu | B28: ±3 | C28: % | D28: Raster pafta izleme — DXF R2010 istenmeli
